Workbook

Sheet Constituyentes
B2: Coeficientes de Maier-Kelley por constituyente
B3: Cp = a + b·T + c·T⁻² [J/mol·K], T en kelvin. Fuente: Barin (1995) / NIST-JANAF.
B4: Constituyente | C4: M (kg/mol) | D4: n átomos | E4: a | F4: b | G4: c | H4: T mín (K) | I4: T máx (K) | J4: 3R/M (J/kg·K) | K4: Nota
B5: MgO | C5: 0.0403 | D5: 2 | E5: 48.98 | F5: 0.00314 | G5: -1134000 | H5: 298 | I5: 3098 | J5: =3*8.3145*D5/C5 -> 1237.8908 | K5: Periclasa
B6: Al2O3 | C6: 0.101961 | D6: 5 | E6: 117.49 | F6: 0.01038 | G6: -3711000 | H6: 298 | I6: 2327 | J6: =3*8.3145*D6/C6 -> 1223.1883 | K6: Corindón
B7: SiO2 (α-cuarzo) | C7: 0.060083 | D7: 3 | E7: 46.94 | F7: 0.03431 | G7: -1130000 | H7: 298 | I7: 847 | J7: =3*8.3145*D7/C7 -> 1245.4521 | K7: Se usa por debajo de 847 K
B8: SiO2 (β-cuarzo) | C8: 0.060083 | D8: 3 | E8: 60.29 | F8: 0.00812 | G8: 0 | H8: 847 | I8: 1696 | J8: =3*8.3145*D8/C8 -> 1245.4521 | K8: Se usa por encima de 847 K
B9: CaO | C9: 0.056077 | D9: 2 | E9: 48.83 | F9: 0.00452 | G9: -653000 | H9: 298 | I9: 2888 | J9: =3*8.3145*D9/C9 -> 889.61606 | K9: Cal
B10: Fe2O3 | C10: 0.159688 | D10: 5 | E10: 98.28 | F10: 0.07782 | G10: -1485000 | H10: 298 | I10: 950 | J10: =3*8.3145*D10/C10 -> 781.00734 | K10: Hematita; rango corto, se satura en 950 K
B11: TiO2 | C11: 0.079866 | D11: 3 | E11: 75.19 | F11: 0.00117 | G11: -1820000 | H11: 298 | I11: 2000 | J11: =3*8.3145*D11/C11 -> 936.95064 | K11: Rutilo
B12: Na2O | C12: 0.061979 | D12: 3 | E12: 66 | F12: 0.016 | G12: -600000 | H12: 298 | I12: 1400 | J12: =3*8.3145*D12/C12 -> 1207.3525 | K12: APROXIMADO (±10 %). Álcali en fase vítrea
B13: K2O | C13: 0.094196 | D13: 3 | E13: 68.5 | F13: 0.02 | G13: -400000 | H13: 298 | I13: 1400 | J13: =3*8.3145*D13/C13 -> 794.41271 | K13: APROXIMADO (±10 %). Álcali en fase vítrea
B14: C (grafito) | C14: 0.012011 | D14: 1 | E14: 17.15 | F14: 0.00427 | G14: -879000 | H14: 298 | I14: 2500 | J14: =3*8.3145*D14/C14 -> 2076.7213 | K14: Grafito + carbono residual del ligante
B16: Verificación rápida a 298 K: MgO ≈ 37.2 · Al2O3 ≈ 79.0 · SiO2 ≈ 44.5 · C ≈ 8.5 J/mol·K (valores tabulados). Si al editar un coeficiente el valor a 298 K se aleja, hay error de captura.
B17: 3R/M es el límite clásico de Dulong-Petit por unidad de masa; se usa en 04 como control de cordura.
B18: Los álcalis (Na2O, K2O) no están tabulados con la misma calidad que los óxidos mayores y en un refractario cocido no existen como óxido libre, sino disueltos en la fase vítrea. Los coeficientes usados reproducen ~3R+20 % a 1000 K, que es lo físicamente esperable. Con ≤ 6 % en masa la incertidumbre que introducen en la mezcla es < 1.5 %.

Sheet CQ's
B2: CQ por capa
B4: A · Análisis como lo reporta el proveedor (% peso)
B5: Capa | C5: Material | D5: MgO | E5: Al2O3 | F5: SiO2 | G5: CaO | H5: Fe2O3 | I5: TiO2 | J5: Na2O | K5: K2O | L5: Σ óxidos | M5: % C fijo
B6: 1 | C6: Trabajo — ANCARBON C F5L10 | D6: 96.4 | E6: 0.3 | F6: 0.8 | G6: 1.6 | H6: 0.7 | I6: 0 | J6: 0 | K6: 0 | L6: =SUM(D6:K6) -> 99.8 | M6: 10
B7: 2 | C7: Junta de sello — COMPAC DRY B83P | D7: 0 | E7: 79 | F7: 12.5 | G7: 0 | H7: 1.8 | I7: 3.2 | J7: 0 | K7: 0 | L7: =SUM(D7:K7) -> 96.5 | M7: 0
B8: 3 | C8: Seguridad — RESISTAL B65 | D8: 0 | E8: 67 | F8: 28 | G8: 0 | H8: 1.7 | I8: 2.8 | J8: 0 | K8: 0 | L8: =SUM(D8:K8) -> 99.5 | M8: 0
B9: 4 | C9: Aislante — SKAMOL VIP 12 HT | D9: 32.6 | E9: 4.3 | F9: 44 | G9: 1.4 | H9: 6.9 | I9: 0.4 | J9: 0.1 | K9: 6.1 | L9: =SUM(D9:K9) -> 95.8 | M9: 0
B11: B · Fracciones másicas normalizadas a base real
B12: Capa | C12: Material | D12: MgO | E12: Al2O3 | F12: SiO2 | G12: CaO | H12: Fe2O3 | I12: TiO2 | J12: Na2O | K12: K2O | L12: C grafito | M12: Σ (control)
B13: =B6 -> 1 | C13: =C6 -> Trabajo — ANCARBON C F5L10 | D13: =IF($L6=0,0,D6/$L6*(1-$M6/100)) -> 0.86933868 | E13: =IF($L6=0,0,E6/$L6*(1-$M6/100)) -> 0.0027054108 | F13: =IF($L6=0,0,F6/$L6*(1-$M6/100)) -> 0.0072144289 | G13: =IF($L6=0,0,G6/$L6*(1-$M6/100)) -> 0.014428858 | H13: =IF($L6=0,0,H6/$L6*(1-$M6/100)) -> 0.0063126253 | I13: =IF($L6=0,0,I6/$L6*(1-$M6/100)) -> 0 | J13: =IF($L6=0,0,J6/$L6*(1-$M6/100)) -> 0 | K13: =IF($L6=0,0,K6/$L6*(1-$M6/100)) -> 0 | L13: =M6/100 -> 0.1 | M13: =SUM(D13:L13) -> 1
B14: =B7 -> 2 | C14: =C7 -> Junta de sello — COMPAC DRY B83P | D14: =IF($L7=0,0,D7/$L7*(1-$M7/100)) -> 0 | E14: =IF($L7=0,0,E7/$L7*(1-$M7/100)) -> 0.81865285 | F14: =IF($L7=0,0,F7/$L7*(1-$M7/100)) -> 0.12953368 | G14: =IF($L7=0,0,G7/$L7*(1-$M7/100)) -> 0 | H14: =IF($L7=0,0,H7/$L7*(1-$M7/100)) -> 0.01865285 | I14: =IF($L7=0,0,I7/$L7*(1-$M7/100)) -> 0.033160622 | J14: =IF($L7=0,0,J7/$L7*(1-$M7/100)) -> 0 | K14: =IF($L7=0,0,K7/$L7*(1-$M7/100)) -> 0 | L14: =M7/100 -> 0 | M14: =SUM(D14:L14) -> 1
B15: =B8 -> 3 | C15: =C8 -> Seguridad — RESISTAL B65 | D15: =IF($L8=0,0,D8/$L8*(1-$M8/100)) -> 0 | E15: =IF($L8=0,0,E8/$L8*(1-$M8/100)) -> 0.67336683 | F15: =IF($L8=0,0,F8/$L8*(1-$M8/100)) -> 0.28140704 | G15: =IF($L8=0,0,G8/$L8*(1-$M8/100)) -> 0 | H15: =IF($L8=0,0,H8/$L8*(1-$M8/100)) -> 0.017085427 | I15: =IF($L8=0,0,I8/$L8*(1-$M8/100)) -> 0.028140704 | J15: =IF($L8=0,0,J8/$L8*(1-$M8/100)) -> 0 | K15: =IF($L8=0,0,K8/$L8*(1-$M8/100)) -> 0 | L15: =M8/100 -> 0 | M15: =SUM(D15:L15) -> 1
B16: =B9 -> 4 | C16: =C9 -> Aislante — SKAMOL VIP 12 HT | D16: =IF($L9=0,0,D9/$L9*(1-$M9/100)) -> 0.34029228 | E16: =IF($L9=0,0,E9/$L9*(1-$M9/100)) -> 0.044885177 | F16: =IF($L9=0,0,F9/$L9*(1-$M9/100)) -> 0.45929019 | G16: =IF($L9=0,0,G9/$L9*(1-$M9/100)) -> 0.014613779 | H16: =IF($L9=0,0,H9/$L9*(1-$M9/100)) -> 0.072025052 | I16: =IF($L9=0,0,I9/$L9*(1-$M9/100)) -> 0.0041753653 | J16: =IF($L9=0,0,J9/$L9*(1-$M9/100)) -> 0.0010438413 | K16: =IF($L9=0,0,K9/$L9*(1-$M9/100)) -> 0.063674322 | L16: =M9/100 -> 0 | M16: =SUM(D16:L16) -> 1
B17: La columna Σ (control) debe dar 1.0000 en las cuatro filas. Si no, hay un error de captura en la sección A.
B18: El orden de las columnas D:L es el MISMO que en 03_cp_constituyentes; no insertar ni mover columnas.

Sheet Cp - Constituyentes
B2: Cp(T) de cada constituyente puro, base másica [J/kg·K]
B3: cp,ᵢ = (a + b·T + c/T²)/Mᵢ con T en K
B4: T (°C) | C4: T (K) | D4: MgO | E4: Al2O3 | F4: SiO2 | G4: CaO | H4: Fe2O3 | I4: TiO2 | J4: Na2O | K4: K2O | L4: C grafito
B5: 25 | C5: =B5+273.15 -> 298.15 | D5: =(Constituyentes!$E$5+Constituyentes!$F$5*MIN(MAX($C5,Constituyentes!$H$5),Constituyentes!$I$5)+Constituyentes!$G$5/MIN(MAX($C5,Constituyentes!$H$5),Constituyentes!$I$5)^2)/Constituyentes!$C$5 -> 922.06803 | E5: =(Constituyentes!$E$6+Constituyentes!$F$6*MIN(MAX($C5,Constituyentes!$H$6),Constituyentes!$I$6)+Constituyentes!$G$6/MIN(MAX($C5,Constituyentes!$H$6),Constituyentes!$I$6)^2)/Constituyentes!$C$6 -> 773.21894 | F5: =IF($C5<Constituyentes!$I$7,(Constituyentes!$E$7+Constituyentes!$F$7*MIN(MAX($C5,Constituyentes!$H$7),Constituyentes!$I$7)+Constituyentes!$G$7/MIN(MAX($C5,Constituyentes!$H$7),Constituyentes!$I$7)^2)/Constituyentes!$C$7,(Constituyentes!$E$8+Constituyentes!$F$8*MIN(MAX($C5,Constituyentes!$H$8),Constituyentes!$I$8)+Constituyentes!$G$8/MIN(MAX($C5,Constituyentes!$H$8),Constituyentes!$I$8)^2)/Constituyentes!$C$8) -> 739.93767 | G5: =(Constituyentes!$E$9+Constituyentes!$F$9*MIN(MAX($C5,Constituyentes!$H$9),Constituyentes!$I$9)+Constituyentes!$G$9/MIN(MAX($C5,Constituyentes!$H$9),Constituyentes!$I$9)^2)/Constituyentes!$C$9 -> 763.80268 | H5: =(Constituyentes!$E$10+Constituyentes!$F$10*MIN(MAX($C5,Constituyentes!$H$10),Constituyentes!$I$10)+Constituyentes!$G$10/MIN(MAX($C5,Constituyentes!$H$10),Constituyentes!$I$10)^2)/Constituyentes!$C$10 -> 656.13343 | I5: =(Constituyentes!$E$11+Constituyentes!$F$11*MIN(MAX($C5,Constituyentes!$H$11),Constituyentes!$I$11)+Constituyentes!$G$11/MIN(MAX($C5,Constituyentes!$H$11),Constituyentes!$I$11)^2)/Constituyentes!$C$11 -> 689.46585 | J5: =(Constituyentes!$E$12+Constituyentes!$F$12*MIN(MAX($C5,Constituyentes!$H$12),Constituyentes!$I$12)+Constituyentes!$G$12/MIN(MAX($C5,Constituyentes!$H$12),Constituyentes!$I$12)^2)/Constituyentes!$C$12 -> 1032.9425 | K5: =(Constituyentes!$E$13+Constituyentes!$F$13*MIN(MAX($C5,Constituyentes!$H$13),Constituyentes!$I$13)+Constituyentes!$G$13/MIN(MAX($C5,Constituyentes!$H$13),Constituyentes!$I$13)^2)/Constituyentes!$C$13 -> 742.74098 | L5: =(Constituyentes!$E$14+Constituyentes!$F$14*MIN(MAX($C5,Constituyentes!$H$14),Constituyentes!$I$14)+Constituyentes!$G$14/MIN(MAX($C5,Constituyentes!$H$14),Constituyentes!$I$14)^2)/Constituyentes!$C$14 -> 710.58653
B6: 100 | C6: =B6+273.15 -> 373.15 | D6: =(Constituyentes!$E$5+Constituyentes!$F$5*MIN(MAX($C6,Constituyentes!$H$5),Constituyentes!$I$5)+Constituyentes!$G$5/MIN(MAX($C6,Constituyentes!$H$5),Constituyentes!$I$5)^2)/Constituyentes!$C$5 -> 1042.3706 | E6: =(Constituyentes!$E$6+Constituyentes!$F$6*MIN(MAX($C6,Constituyentes!$H$6),Constituyentes!$I$6)+Constituyentes!$G$6/MIN(MAX($C6,Constituyentes!$H$6),Constituyentes!$I$6)^2)/Constituyentes!$C$6 -> 928.90075 | F6: =IF($C6<Constituyentes!$I$7,(Constituyentes!$E$7+Constituyentes!$F$7*MIN(MAX($C6,Constituyentes!$H$7),Constituyentes!$I$7)+Constituyentes!$G$7/MIN(MAX($C6,Constituyentes!$H$7),Constituyentes!$I$7)^2)/Constituyentes!$C$7,(Constituyentes!$E$8+Constituyentes!$F$8*MIN(MAX($C6,Constituyentes!$H$8),Constituyentes!$I$8)+Constituyentes!$G$8/MIN(MAX($C6,Constituyentes!$H$8),Constituyentes!$I$8)^2)/Constituyentes!$C$8) -> 859.26712 | G6: =(Constituyentes!$E$9+Constituyentes!$F$9*MIN(MAX($C6,Constituyentes!$H$9),Constituyentes!$I$9)+Constituyentes!$G$9/MIN(MAX($C6,Constituyentes!$H$9),Constituyentes!$I$9)^2)/Constituyentes!$C$9 -> 817.21427 | H6: =(Constituyentes!$E$10+Constituyentes!$F$10*MIN(MAX($C6,Constituyentes!$H$10),Constituyentes!$I$10)+Constituyentes!$G$10/MIN(MAX($C6,Constituyentes!$H$10),Constituyentes!$I$10)^2)/Constituyentes!$C$10 -> 730.50927 | I6: =(Constituyentes!$E$11+Constituyentes!$F$11*MIN(MAX($C6,Constituyentes!$H$11),Constituyentes!$I$11)+Constituyentes!$G$11/MIN(MAX($C6,Constituyentes!$H$11),Constituyentes!$I$11)^2)/Constituyentes!$C$11 -> 783.2584 | J6: =(Constituyentes!$E$12+Constituyentes!$F$12*MIN(MAX($C6,Constituyentes!$H$12),Constituyentes!$I$12)+Constituyentes!$G$12/MIN(MAX($C6,Constituyentes!$H$12),Constituyentes!$I$12)^2)/Constituyentes!$C$12 -> 1091.6814 | K6: =(Constituyentes!$E$13+Constituyentes!$F$13*MIN(MAX($C6,Constituyentes!$H$13),Constituyentes!$I$13)+Constituyentes!$G$13/MIN(MAX($C6,Constituyentes!$H$13),Constituyentes!$I$13)^2)/Constituyentes!$C$13 -> 775.93827 | L6: =(Constituyentes!$E$14+Constituyentes!$F$14*MIN(MAX($C6,Constituyentes!$H$14),Constituyentes!$I$14)+Constituyentes!$G$14/MIN(MAX($C6,Constituyentes!$H$14),Constituyentes!$I$14)^2)/Constituyentes!$C$14 -> 1034.9306
B7: 200 | C7: =B7+273.15 -> 473.15 | D7: =(Constituyentes!$E$5+Constituyentes!$F$5*MIN(MAX($C7,Constituyentes!$H$5),Constituyentes!$I$5)+Constituyentes!$G$5/MIN(MAX($C7,Constituyentes!$H$5),Constituyentes!$I$5)^2)/Constituyentes!$C$5 -> 1126.5576 | E7: =(Constituyentes!$E$6+Constituyentes!$F$6*MIN(MAX($C7,Constituyentes!$H$6),Constituyentes!$I$6)+Constituyentes!$G$6/MIN(MAX($C7,Constituyentes!$H$6),Constituyentes!$I$6)^2)/Constituyentes!$C$6 -> 1037.8947 | F7: =IF($C7<Constituyentes!$I$7,(Constituyentes!$E$7+Constituyentes!$F$7*MIN(MAX($C7,Constituyentes!$H$7),Constituyentes!$I$7)+Constituyentes!$G$7/MIN(MAX($C7,Constituyentes!$H$7),Constituyentes!$I$7)^2)/Constituyentes!$C$7,(Constituyentes!$E$8+Constituyentes!$F$8*MIN(MAX($C7,Constituyentes!$H$8),Constituyentes!$I$8)+Constituyentes!$G$8/MIN(MAX($C7,Constituyentes!$H$8),Constituyentes!$I$8)^2)/Constituyentes!$C$8) -> 967.43214 | G7: =(Constituyentes!$E$9+Constituyentes!$F$9*MIN(MAX($C7,Constituyentes!$H$9),Constituyentes!$I$9)+Constituyentes!$G$9/MIN(MAX($C7,Constituyentes!$H$9),Constituyentes!$I$9)^2)/Constituyentes!$C$9 -> 856.88925 | H7: =(Constituyentes!$E$10+Constituyentes!$F$10*MIN(MAX($C7,Constituyentes!$H$10),Constituyentes!$I$10)+Constituyentes!$G$10/MIN(MAX($C7,Constituyentes!$H$10),Constituyentes!$I$10)^2)/Constituyentes!$C$10 -> 804.48904 | I7: =(Constituyentes!$E$11+Constituyentes!$F$11*MIN(MAX($C7,Constituyentes!$H$11),Constituyentes!$I$11)+Constituyentes!$G$11/MIN(MAX($C7,Constituyentes!$H$11),Constituyentes!$I$11)^2)/Constituyentes!$C$11 -> 846.5918 | J7: =(Constituyentes!$E$12+Constituyentes!$F$12*MIN(MAX($C7,Constituyentes!$H$12),Constituyentes!$I$12)+Constituyentes!$G$12/MIN(MAX($C7,Constituyentes!$H$12),Constituyentes!$I$12)^2)/Constituyentes!$C$12 -> 1143.7791 | K7: =(Constituyentes!$E$13+Constituyentes!$F$13*MIN(MAX($C7,Constituyentes!$H$13),Constituyentes!$I$13)+Constituyentes!$G$13/MIN(MAX($C7,Constituyentes!$H$13),Constituyentes!$I$13)^2)/Constituyentes!$C$13 -> 808.69948 | L7: =(Constituyentes!$E$14+Constituyentes!$F$14*MIN(MAX($C7,Constituyentes!$H$14),Constituyentes!$I$14)+Constituyentes!$G$14/MIN(MAX($C7,Constituyentes!$H$14),Constituyentes!$I$14)^2)/Constituyentes!$C$14 -> 1269.1683
B8: 300 | C8: =B8+273.15 -> 573.15 | D8: =(Constituyentes!$E$5+Constituyentes!$F$5*MIN(MAX($C8,Constituyentes!$H$5),Constituyentes!$I$5)+Constituyentes!$G$5/MIN(MAX($C8,Constituyentes!$H$5),Constituyentes!$I$5)^2)/Constituyentes!$C$5 -> 1174.3833 | E8: =(Constituyentes!$E$6+Constituyentes!$F$6*MIN(MAX($C8,Constituyentes!$H$6),Constituyentes!$I$6)+Constituyentes!$G$6/MIN(MAX($C8,Constituyentes!$H$6),Constituyentes!$I$6)^2)/Constituyentes!$C$6 -> 1099.8571 | F8: =IF($C8<Constituyentes!$I$7,(Constituyentes!$E$7+Constituyentes!$F$7*MIN(MAX($C8,Constituyentes!$H$7),Constituyentes!$I$7)+Constituyentes!$G$7/MIN(MAX($C8,Constituyentes!$H$7),Constituyentes!$I$7)^2)/Constituyentes!$C$7,(Constituyentes!$E$8+Constituyentes!$F$8*MIN(MAX($C8,Constituyentes!$H$8),Constituyentes!$I$8)+Constituyentes!$G$8/MIN(MAX($C8,Constituyentes!$H$8),Constituyentes!$I$8)^2)/Constituyentes!$C$8) -> 1051.2942 | G8: =(Constituyentes!$E$9+Constituyentes!$F$9*MIN(MAX($C8,Constituyentes!$H$9),Constituyentes!$I$9)+Constituyentes!$G$9/MIN(MAX($C8,Constituyentes!$H$9),Constituyentes!$I$9)^2)/Constituyentes!$C$9 -> 881.51685 | H8: =(Constituyentes!$E$10+Constituyentes!$F$10*MIN(MAX($C8,Constituyentes!$H$10),Constituyentes!$I$10)+Constituyentes!$G$10/MIN(MAX($C8,Constituyentes!$H$10),Constituyentes!$I$10)^2)/Constituyentes!$C$10 -> 866.45207 | I8: =(Constituyentes!$E$11+Constituyentes!$F$11*MIN(MAX($C8,Constituyentes!$H$11),Constituyentes!$I$11)+Constituyentes!$G$11/MIN(MAX($C8,Constituyentes!$H$11),Constituyentes!$I$11)^2)/Constituyentes!$C$11 -> 880.47813 | J8: =(Constituyentes!$E$12+Constituyentes!$F$12*MIN(MAX($C8,Constituyentes!$H$12),Constituyentes!$I$12)+Constituyentes!$G$12/MIN(MAX($C8,Constituyentes!$H$12),Constituyentes!$I$12)^2)/Constituyentes!$C$12 -> 1183.3673 | K8: =(Constituyentes!$E$13+Constituyentes!$F$13*MIN(MAX($C8,Constituyentes!$H$13),Constituyentes!$I$13)+Constituyentes!$G$13/MIN(MAX($C8,Constituyentes!$H$13),Constituyentes!$I$13)^2)/Constituyentes!$C$13 -> 835.97337 | L8: =(Constituyentes!$E$14+Constituyentes!$F$14*MIN(MAX($C8,Constituyentes!$H$14),Constituyentes!$I$14)+Constituyentes!$G$14/MIN(MAX($C8,Constituyentes!$H$14),Constituyentes!$I$14)^2)/Constituyentes!$C$14 -> 1408.8385
B9: 400 | C9: =B9+273.15 -> 673.15 | D9: =(Constituyentes!$E$5+Constituyentes!$F$5*MIN(MAX($C9,Constituyentes!$H$5),Constituyentes!$I$5)+Constituyentes!$G$5/MIN(MAX($C9,Constituyentes!$H$5),Constituyentes!$I$5)^2)/Constituyentes!$C$5 -> 1205.7346 | E9: =(Constituyentes!$E$6+Constituyentes!$F$6*MIN(MAX($C9,Constituyentes!$H$6),Constituyentes!$I$6)+Constituyentes!$G$6/MIN(MAX($C9,Constituyentes!$H$6),Constituyentes!$I$6)^2)/Constituyentes!$C$6 -> 1140.5107 | F9: =IF($C9<Constituyentes!$I$7,(Constituyentes!$E$7+Constituyentes!$F$7*MIN(MAX($C9,Constituyentes!$H$7),Constituyentes!$I$7)+Constituyentes!$G$7/MIN(MAX($C9,Constituyentes!$H$7),Constituyentes!$I$7)^2)/Constituyentes!$C$7,(Constituyentes!$E$8+Constituyentes!$F$8*MIN(MAX($C9,Constituyentes!$H$8),Constituyentes!$I$8)+Constituyentes!$G$8/MIN(MAX($C9,Constituyentes!$H$8),Constituyentes!$I$8)^2)/Constituyentes!$C$8) -> 1124.1452 | G9: =(Constituyentes!$E$9+Constituyentes!$F$9*MIN(MAX($C9,Constituyentes!$H$9),Constituyentes!$I$9)+Constituyentes!$G$9/MIN(MAX($C9,Constituyentes!$H$9),Constituyentes!$I$9)^2)/Constituyentes!$C$9 -> 899.32688 | H9: =(Constituyentes!$E$10+Constituyentes!$F$10*MIN(MAX($C9,Constituyentes!$H$10),Constituyentes!$I$10)+Constituyentes!$G$10/MIN(MAX($C9,Constituyentes!$H$10),Constituyentes!$I$10)^2)/Constituyentes!$C$10 -> 922.97063 | I9: =(Constituyentes!$E$11+Constituyentes!$F$11*MIN(MAX($C9,Constituyentes!$H$11),Constituyentes!$I$11)+Constituyentes!$G$11/MIN(MAX($C9,Constituyentes!$H$11),Constituyentes!$I$11)^2)/Constituyentes!$C$11 -> 901.02279 | J9: =(Constituyentes!$E$12+Constituyentes!$F$12*MIN(MAX($C9,Constituyentes!$H$12),Constituyentes!$I$12)+Constituyentes!$G$12/MIN(MAX($C9,Constituyentes!$H$12),Constituyentes!$I$12)^2)/Constituyentes!$C$12 -> 1217.2878 | K9: =(Constituyentes!$E$13+Constituyentes!$F$13*MIN(MAX($C9,Constituyentes!$H$13),Constituyentes!$I$13)+Constituyentes!$G$13/MIN(MAX($C9,Constituyentes!$H$13),Constituyentes!$I$13)^2)/Constituyentes!$C$13 -> 860.7611 | L9: =(Constituyentes!$E$14+Constituyentes!$F$14*MIN(MAX($C9,Constituyentes!$H$14),Constituyentes!$I$14)+Constituyentes!$G$14/MIN(MAX($C9,Constituyentes!$H$14),Constituyentes!$I$14)^2)/Constituyentes!$C$14 -> 1505.6626
B10: 500 | C10: =B10+273.15 -> 773.15 | D10: =(Constituyentes!$E$5+Constituyentes!$F$5*MIN(MAX($C10,Constituyentes!$H$5),Constituyentes!$I$5)+Constituyentes!$G$5/MIN(MAX($C10,Constituyentes!$H$5),Constituyentes!$I$5)^2)/Constituyentes!$C$5 -> 1228.5512 | E10: =(Constituyentes!$E$6+Constituyentes!$F$6*MIN(MAX($C10,Constituyentes!$H$6),Constituyentes!$I$6)+Constituyentes!$G$6/MIN(MAX($C10,Constituyentes!$H$6),Constituyentes!$I$6)^2)/Constituyentes!$C$6 -> 1170.1251 | F10: =IF($C10<Constituyentes!$I$7,(Constituyentes!$E$7+Constituyentes!$F$7*MIN(MAX($C10,Constituyentes!$H$7),Constituyentes!$I$7)+Constituyentes!$G$7/MIN(MAX($C10,Constituyentes!$H$7),Constituyentes!$I$7)^2)/Constituyentes!$C$7,(Constituyentes!$E$8+Constituyentes!$F$8*MIN(MAX($C10,Constituyentes!$H$8),Constituyentes!$I$8)+Constituyentes!$G$8/MIN(MAX($C10,Constituyentes!$H$8),Constituyentes!$I$8)^2)/Constituyentes!$C$8) -> 1191.2919 | G10: =(Constituyentes!$E$9+Constituyentes!$F$9*MIN(MAX($C10,Constituyentes!$H$9),Constituyentes!$I$9)+Constituyentes!$G$9/MIN(MAX($C10,Constituyentes!$H$9),Constituyentes!$I$9)^2)/Constituyentes!$C$9 -> 913.60501 | H10: =(Constituyentes!$E$10+Constituyentes!$F$10*MIN(MAX($C10,Constituyentes!$H$10),Constituyentes!$I$10)+Constituyentes!$G$10/MIN(MAX($C10,Constituyentes!$H$10),Constituyentes!$I$10)^2)/Constituyentes!$C$10 -> 976.66864 | I10: =(Constituyentes!$E$11+Constituyentes!$F$11*MIN(MAX($C10,Constituyentes!$H$11),Constituyentes!$I$11)+Constituyentes!$G$11/MIN(MAX($C10,Constituyentes!$H$11),Constituyentes!$I$11)^2)/Constituyentes!$C$11 -> 914.65567 | J10: =(Constituyentes!$E$12+Constituyentes!$F$12*MIN(MAX($C10,Constituyentes!$H$12),Constituyentes!$I$12)+Constituyentes!$G$12/MIN(MAX($C10,Constituyentes!$H$12),Constituyentes!$I$12)^2)/Constituyentes!$C$12 -> 1248.2721 | K10: =(Constituyentes!$E$13+Constituyentes!$F$13*MIN(MAX($C10,Constituyentes!$H$13),Constituyentes!$I$13)+Constituyentes!$G$13/MIN(MAX($C10,Constituyentes!$H$13),Constituyentes!$I$13)^2)/Constituyentes!$C$13 -> 884.26086 | L10: =(Constituyentes!$E$14+Constituyentes!$F$14*MIN(MAX($C10,Constituyentes!$H$14),Constituyentes!$I$14)+Constituyentes!$G$14/MIN(MAX($C10,Constituyentes!$H$14),Constituyentes!$I$14)^2)/Constituyentes!$C$14 -> 1580.29
B11: 600 | C11: =B11+273.15 -> 873.15 | D11: =(Constituyentes!$E$5+Constituyentes!$F$5*MIN(MAX($C11,Constituyentes!$H$5),Constituyentes!$I$5)+Constituyentes!$G$5/MIN(MAX($C11,Constituyentes!$H$5),Constituyentes!$I$5)^2)/Constituyentes!$C$5 -> 1246.5078 | E11: =(Constituyentes!$E$6+Constituyentes!$F$6*MIN(MAX($C11,Constituyentes!$H$6),Constituyentes!$I$6)+Constituyentes!$G$6/MIN(MAX($C11,Constituyentes!$H$6),Constituyentes!$I$6)^2)/Constituyentes!$C$6 -> 1193.4535 | F11: =IF($C11<Constituyentes!$I$7,(Constituyentes!$E$7+Constituyentes!$F$7*MIN(MAX($C11,Constituyentes!$H$7),Constituyentes!$I$7)+Constituyentes!$G$7/MIN(MAX($C11,Constituyentes!$H$7),Constituyentes!$I$7)^2)/Constituyentes!$C$7,(Constituyentes!$E$8+Constituyentes!$F$8*MIN(MAX($C11,Constituyentes!$H$8),Constituyentes!$I$8)+Constituyentes!$G$8/MIN(MAX($C11,Constituyentes!$H$8),Constituyentes!$I$8)^2)/Constituyentes!$C$8) -> 1121.4483 | G11: =(Constituyentes!$E$9+Constituyentes!$F$9*MIN(MAX($C11,Constituyentes!$H$9),Constituyentes!$I$9)+Constituyentes!$G$9/MIN(MAX($C11,Constituyentes!$H$9),Constituyentes!$I$9)^2)/Constituyentes!$C$9 -> 925.87196 | H11: =(Constituyentes!$E$10+Constituyentes!$F$10*MIN(MAX($C11,Constituyentes!$H$10),Constituyentes!$I$10)+Constituyentes!$G$10/MIN(MAX($C11,Constituyentes!$H$10),Constituyentes!$I$10)^2)/Constituyentes!$C$10 -> 1028.7605 | I11: =(Constituyentes!$E$11+Constituyentes!$F$11*MIN(MAX($C11,Constituyentes!$H$11),Constituyentes!$I$11)+Constituyentes!$G$11/MIN(MAX($C11,Constituyentes!$H$11),Constituyentes!$I$11)^2)/Constituyentes!$C$11 -> 924.35278 | J11: =(Constituyentes!$E$12+Constituyentes!$F$12*MIN(MAX($C11,Constituyentes!$H$12),Constituyentes!$I$12)+Constituyentes!$G$12/MIN(MAX($C11,Constituyentes!$H$12),Constituyentes!$I$12)^2)/Constituyentes!$C$12 -> 1277.5844 | K11: =(Constituyentes!$E$13+Constituyentes!$F$13*MIN(MAX($C11,Constituyentes!$H$13),Constituyentes!$I$13)+Constituyentes!$G$13/MIN(MAX($C11,Constituyentes!$H$13),Constituyentes!$I$13)^2)/Constituyentes!$C$13 -> 907.02721 | L11: =(Constituyentes!$E$14+Constituyentes!$F$14*MIN(MAX($C11,Constituyentes!$H$14),Constituyentes!$I$14)+Constituyentes!$G$14/MIN(MAX($C11,Constituyentes!$H$14),Constituyentes!$I$14)^2)/Constituyentes!$C$14 -> 1642.2778
B12: 700 | C12: =B12+273.15 -> 973.15 | D12: =(Constituyentes!$E$5+Constituyentes!$F$5*MIN(MAX($C12,Constituyentes!$H$5),Constituyentes!$I$5)+Constituyentes!$G$5/MIN(MAX($C12,Constituyentes!$H$5),Constituyentes!$I$5)^2)/Constituyentes!$C$5 -> 1261.4951 | E12: =(Constituyentes!$E$6+Constituyentes!$F$6*MIN(MAX($C12,Constituyentes!$H$6),Constituyentes!$I$6)+Constituyentes!$G$6/MIN(MAX($C12,Constituyentes!$H$6),Constituyentes!$I$6)^2)/Constituyentes!$C$6 -> 1212.9412 | F12: =IF($C12<Constituyentes!$I$7,(Constituyentes!$E$7+Constituyentes!$F$7*MIN(MAX($C12,Constituyentes!$H$7),Constituyentes!$I$7)+Constituyentes!$G$7/MIN(MAX($C12,Constituyentes!$H$7),Constituyentes!$I$7)^2)/Constituyentes!$C$7,(Constituyentes!$E$8+Constituyentes!$F$8*MIN(MAX($C12,Constituyentes!$H$8),Constituyentes!$I$8)+Constituyentes!$G$8/MIN(MAX($C12,Constituyentes!$H$8),Constituyentes!$I$8)^2)/Constituyentes!$C$8) -> 1134.9629 | G12: =(Constituyentes!$E$9+Constituyentes!$F$9*MIN(MAX($C12,Constituyentes!$H$9),Constituyentes!$I$9)+Constituyentes!$G$9/MIN(MAX($C12,Constituyentes!$H$9),Constituyentes!$I$9)^2)/Constituyentes!$C$9 -> 936.91009 | H12: =(Constituyentes!$E$10+Constituyentes!$F$10*MIN(MAX($C12,Constituyentes!$H$10),Constituyentes!$I$10)+Constituyentes!$G$10/MIN(MAX($C12,Constituyentes!$H$10),Constituyentes!$I$10)^2)/Constituyentes!$C$10 -> 1068.1051 | I12: =(Constituyentes!$E$11+Constituyentes!$F$11*MIN(MAX($C12,Constituyentes!$H$11),Constituyentes!$I$11)+Constituyentes!$G$11/MIN(MAX($C12,Constituyentes!$H$11),Constituyentes!$I$11)^2)/Constituyentes!$C$11 -> 931.64512 | J12: =(Constituyentes!$E$12+Constituyentes!$F$12*MIN(MAX($C12,Constituyentes!$H$12),Constituyentes!$I$12)+Constituyentes!$G$12/MIN(MAX($C12,Constituyentes!$H$12),Constituyentes!$I$12)^2)/Constituyentes!$C$12 -> 1305.8751 | K12: =(Constituyentes!$E$13+Constituyentes!$F$13*MIN(MAX($C12,Constituyentes!$H$13),Constituyentes!$I$13)+Constituyentes!$G$13/MIN(MAX($C12,Constituyentes!$H$13),Constituyentes!$I$13)^2)/Constituyentes!$C$13 -> 929.34544 | L12: =(Constituyentes!$E$14+Constituyentes!$F$14*MIN(MAX($C12,Constituyentes!$H$14),Constituyentes!$I$14)+Constituyentes!$G$14/MIN(MAX($C12,Constituyentes!$H$14),Constituyentes!$I$14)^2)/Constituyentes!$C$14 -> 1696.5429
B13: 800 | C13: =B13+273.15 -> 1073.15 | D13: =(Constituyentes!$E$5+Constituyentes!$F$5*MIN(MAX($C13,Constituyentes!$H$5),Constituyentes!$I$5)+Constituyentes!$G$5/MIN(MAX($C13,Constituyentes!$H$5),Constituyentes!$I$5)^2)/Constituyentes!$C$5 -> 1274.5662 | E13: =(Constituyentes!$E$6+Constituyentes!$F$6*MIN(MAX($C13,Constituyentes!$H$6),Constituyentes!$I$6)+Constituyentes!$G$6/MIN(MAX($C13,Constituyentes!$H$6),Constituyentes!$I$6)^2)/Constituyentes!$C$6 -> 1229.9503 | F13: =IF($C13<Constituyentes!$I$7,(Constituyentes!$E$7+Constituyentes!$F$7*MIN(MAX($C13,Constituyentes!$H$7),Constituyentes!$I$7)+Constituyentes!$G$7/MIN(MAX($C13,Constituyentes!$H$7),Constituyentes!$I$7)^2)/Constituyentes!$C$7,(Constituyentes!$E$8+Constituyentes!$F$8*MIN(MAX($C13,Constituyentes!$H$8),Constituyentes!$I$8)+Constituyentes!$G$8/MIN(MAX($C13,Constituyentes!$H$8),Constituyentes!$I$8)^2)/Constituyentes!$C$8) -> 1148.4776 | G13: =(Constituyentes!$E$9+Constituyentes!$F$9*MIN(MAX($C13,Constituyentes!$H$9),Constituyentes!$I$9)+Constituyentes!$G$9/MIN(MAX($C13,Constituyentes!$H$9),Constituyentes!$I$9)^2)/Constituyentes!$C$9 -> 947.15527 | H13: =(Constituyentes!$E$10+Constituyentes!$F$10*MIN(MAX($C13,Constituyentes!$H$10),Constituyentes!$I$10)+Constituyentes!$G$10/MIN(MAX($C13,Constituyentes!$H$10),Constituyentes!$I$10)^2)/Constituyentes!$C$10 -> 1068.1051 | I13: =(Constituyentes!$E$11+Constituyentes!$F$11*MIN(MAX($C13,Constituyentes!$H$11),Constituyentes!$I$11)+Constituyentes!$G$11/MIN(MAX($C13,Constituyentes!$H$11),Constituyentes!$I$11)^2)/Constituyentes!$C$11 -> 937.38569 | J13: =(Constituyentes!$E$12+Constituyentes!$F$12*MIN(MAX($C13,Constituyentes!$H$12),Constituyentes!$I$12)+Constituyentes!$G$12/MIN(MAX($C13,Constituyentes!$H$12),Constituyentes!$I$12)^2)/Constituyentes!$C$12 -> 1333.5067 | K13: =(Constituyentes!$E$13+Constituyentes!$F$13*MIN(MAX($C13,Constituyentes!$H$13),Constituyentes!$I$13)+Constituyentes!$G$13/MIN(MAX($C13,Constituyentes!$H$13),Constituyentes!$I$13)^2)/Constituyentes!$C$13 -> 951.3745 | L13: =(Constituyentes!$E$14+Constituyentes!$F$14*MIN(MAX($C13,Constituyentes!$H$14),Constituyentes!$I$14)+Constituyentes!$G$14/MIN(MAX($C13,Constituyentes!$H$14),Constituyentes!$I$14)^2)/Constituyentes!$C$14 -> 1745.8245
B14: 900 | C14: =B14+273.15 -> 1173.15 | D14: =(Constituyentes!$E$5+Constituyentes!$F$5*MIN(MAX($C14,Constituyentes!$H$5),Constituyentes!$I$5)+Constituyentes!$G$5/MIN(MAX($C14,Constituyentes!$H$5),Constituyentes!$I$5)^2)/Constituyentes!$C$5 -> 1286.3457 | E14: =(Constituyentes!$E$6+Constituyentes!$F$6*MIN(MAX($C14,Constituyentes!$H$6),Constituyentes!$I$6)+Constituyentes!$G$6/MIN(MAX($C14,Constituyentes!$H$6),Constituyentes!$I$6)^2)/Constituyentes!$C$6 -> 1245.2889 | F14: =IF($C14<Constituyentes!$I$7,(Constituyentes!$E$7+Constituyentes!$F$7*MIN(MAX($C14,Constituyentes!$H$7),Constituyentes!$I$7)+Constituyentes!$G$7/MIN(MAX($C14,Constituyentes!$H$7),Constituyentes!$I$7)^2)/Constituyentes!$C$7,(Constituyentes!$E$8+Constituyentes!$F$8*MIN(MAX($C14,Constituyentes!$H$8),Constituyentes!$I$8)+Constituyentes!$G$8/MIN(MAX($C14,Constituyentes!$H$8),Constituyentes!$I$8)^2)/Constituyentes!$C$8) -> 1161.9922 | G14: =(Constituyentes!$E$9+Constituyentes!$F$9*MIN(MAX($C14,Constituyentes!$H$9),Constituyentes!$I$9)+Constituyentes!$G$9/MIN(MAX($C14,Constituyentes!$H$9),Constituyentes!$I$9)^2)/Constituyentes!$C$9 -> 956.86593 | H14: =(Constituyentes!$E$10+Constituyentes!$F$10*MIN(MAX($C14,Constituyentes!$H$10),Constituyentes!$I$10)+Constituyentes!$G$10/MIN(MAX($C14,Constituyentes!$H$10),Constituyentes!$I$10)^2)/Constituyentes!$C$10 -> 1068.1051 | I14: =(Constituyentes!$E$11+Constituyentes!$F$11*MIN(MAX($C14,Constituyentes!$H$11),Constituyentes!$I$11)+Constituyentes!$G$11/MIN(MAX($C14,Constituyentes!$H$11),Constituyentes!$I$11)^2)/Constituyentes!$C$11 -> 942.08025 | J14: =(Constituyentes!$E$12+Constituyentes!$F$12*MIN(MAX($C14,Constituyentes!$H$12),Constituyentes!$I$12)+Constituyentes!$G$12/MIN(MAX($C14,Constituyentes!$H$12),Constituyentes!$I$12)^2)/Constituyentes!$C$12 -> 1360.6938 | K14: =(Constituyentes!$E$13+Constituyentes!$F$13*MIN(MAX($C14,Constituyentes!$H$13),Constituyentes!$I$13)+Constituyentes!$G$13/MIN(MAX($C14,Constituyentes!$H$13),Constituyentes!$I$13)^2)/Constituyentes!$C$13 -> 973.20865 | L14: =(Constituyentes!$E$14+Constituyentes!$F$14*MIN(MAX($C14,Constituyentes!$H$14),Constituyentes!$I$14)+Constituyentes!$G$14/MIN(MAX($C14,Constituyentes!$H$14),Constituyentes!$I$14)^2)/Constituyentes!$C$14 -> 1791.747
B15: 1000 | C15: =B15+273.15 -> 1273.15 | D15: =(Constituyentes!$E$5+Constituyentes!$F$5*MIN(MAX($C15,Constituyentes!$H$5),Constituyentes!$I$5)+Constituyentes!$G$5/MIN(MAX($C15,Constituyentes!$H$5),Constituyentes!$I$5)^2)/Constituyentes!$C$5 -> 1297.2229 | E15: =(Constituyentes!$E$6+Constituyentes!$F$6*MIN(MAX($C15,Constituyentes!$H$6),Constituyentes!$I$6)+Constituyentes!$G$6/MIN(MAX($C15,Constituyentes!$H$6),Constituyentes!$I$6)^2)/Constituyentes!$C$6 -> 1259.4604 | F15: =IF($C15<Constituyentes!$I$7,(Constituyentes!$E$7+Constituyentes!$F$7*MIN(MAX($C15,Constituyentes!$H$7),Constituyentes!$I$7)+Constituyentes!$G$7/MIN(MAX($C15,Constituyentes!$H$7),Constituyentes!$I$7)^2)/Constituyentes!$C$7,(Constituyentes!$E$8+Constituyentes!$F$8*MIN(MAX($C15,Constituyentes!$H$8),Constituyentes!$I$8)+Constituyentes!$G$8/MIN(MAX($C15,Constituyentes!$H$8),Constituyentes!$I$8)^2)/Constituyentes!$C$8) -> 1175.5068 | G15: =(Constituyentes!$E$9+Constituyentes!$F$9*MIN(MAX($C15,Constituyentes!$H$9),Constituyentes!$I$9)+Constituyentes!$G$9/MIN(MAX($C15,Constituyentes!$H$9),Constituyentes!$I$9)^2)/Constituyentes!$C$9 -> 966.20322 | H15: =(Constituyentes!$E$10+Constituyentes!$F$10*MIN(MAX($C15,Constituyentes!$H$10),Constituyentes!$I$10)+Constituyentes!$G$10/MIN(MAX($C15,Constituyentes!$H$10),Constituyentes!$I$10)^2)/Constituyentes!$C$10 -> 1068.1051 | I15: =(Constituyentes!$E$11+Constituyentes!$F$11*MIN(MAX($C15,Constituyentes!$H$11),Constituyentes!$I$11)+Constituyentes!$G$11/MIN(MAX($C15,Constituyentes!$H$11),Constituyentes!$I$11)^2)/Constituyentes!$C$11 -> 946.04412 | J15: =(Constituyentes!$E$12+Constituyentes!$F$12*MIN(MAX($C15,Constituyentes!$H$12),Constituyentes!$I$12)+Constituyentes!$G$12/MIN(MAX($C15,Constituyentes!$H$12),Constituyentes!$I$12)^2)/Constituyentes!$C$12 -> 1387.5706 | K15: =(Constituyentes!$E$13+Constituyentes!$F$13*MIN(MAX($C15,Constituyentes!$H$13),Constituyentes!$I$13)+Constituyentes!$G$13/MIN(MAX($C15,Constituyentes!$H$13),Constituyentes!$I$13)^2)/Constituyentes!$C$13 -> 994.90663 | L15: =(Constituyentes!$E$14+Constituyentes!$F$14*MIN(MAX($C15,Constituyentes!$H$14),Constituyentes!$I$14)+Constituyentes!$G$14/MIN(MAX($C15,Constituyentes!$H$14),Constituyentes!$I$14)^2)/Constituyentes!$C$14 -> 1835.3229
B16: 1100 | C16: =B16+273.15 -> 1373.15 | D16: =(Constituyentes!$E$5+Constituyentes!$F$5*MIN(MAX($C16,Constituyentes!$H$5),Constituyentes!$I$5)+Constituyentes!$G$5/MIN(MAX($C16,Constituyentes!$H$5),Constituyentes!$I$5)^2)/Constituyentes!$C$5 -> 1307.4509 | E16: =(Constituyentes!$E$6+Constituyentes!$F$6*MIN(MAX($C16,Constituyentes!$H$6),Constituyentes!$I$6)+Constituyentes!$G$6/MIN(MAX($C16,Constituyentes!$H$6),Constituyentes!$I$6)^2)/Constituyentes!$C$6 -> 1272.7922 | F16: =IF($C16<Constituyentes!$I$7,(Constituyentes!$E$7+Constituyentes!$F$7*MIN(MAX($C16,Constituyentes!$H$7),Constituyentes!$I$7)+Constituyentes!$G$7/MIN(MAX($C16,Constituyentes!$H$7),Constituyentes!$I$7)^2)/Constituyentes!$C$7,(Constituyentes!$E$8+Constituyentes!$F$8*MIN(MAX($C16,Constituyentes!$H$8),Constituyentes!$I$8)+Constituyentes!$G$8/MIN(MAX($C16,Constituyentes!$H$8),Constituyentes!$I$8)^2)/Constituyentes!$C$8) -> 1189.0215 | G16: =(Constituyentes!$E$9+Constituyentes!$F$9*MIN(MAX($C16,Constituyentes!$H$9),Constituyentes!$I$9)+Constituyentes!$G$9/MIN(MAX($C16,Constituyentes!$H$9),Constituyentes!$I$9)^2)/Constituyentes!$C$9 -> 975.27183 | H16: =(Constituyentes!$E$10+Constituyentes!$F$10*MIN(MAX($C16,Constituyentes!$H$10),Constituyentes!$I$10)+Constituyentes!$G$10/MIN(MAX($C16,Constituyentes!$H$10),Constituyentes!$I$10)^2)/Constituyentes!$C$10 -> 1068.1051 | I16: =(Constituyentes!$E$11+Constituyentes!$F$11*MIN(MAX($C16,Constituyentes!$H$11),Constituyentes!$I$11)+Constituyentes!$G$11/MIN(MAX($C16,Constituyentes!$H$11),Constituyentes!$I$11)^2)/Constituyentes!$C$11 -> 949.4822 | J16: =(Constituyentes!$E$12+Constituyentes!$F$12*MIN(MAX($C16,Constituyentes!$H$12),Constituyentes!$I$12)+Constituyentes!$G$12/MIN(MAX($C16,Constituyentes!$H$12),Constituyentes!$I$12)^2)/Constituyentes!$C$12 -> 1414.224 | K16: =(Constituyentes!$E$13+Constituyentes!$F$13*MIN(MAX($C16,Constituyentes!$H$13),Constituyentes!$I$13)+Constituyentes!$G$13/MIN(MAX($C16,Constituyentes!$H$13),Constituyentes!$I$13)^2)/Constituyentes!$C$13 -> 1016.5066 | L16: =(Constituyentes!$E$14+Constituyentes!$F$14*MIN(MAX($C16,Constituyentes!$H$14),Constituyentes!$I$14)+Constituyentes!$G$14/MIN(MAX($C16,Constituyentes!$H$14),Constituyentes!$I$14)^2)/Constituyentes!$C$14 -> 1877.2102
... B21: 1600 | C21: =B21+273.15 -> 1873.15 | D21: =(Constituyentes!$E$5+Constituyentes!$F$5*MIN(MAX($C21,Constituyentes!$H$5),Constituyentes!$I$5)+Constituyentes!$G$5/MIN(MAX($C21,Constituyentes!$H$5),Constituyentes!$I$5)^2)/Constituyentes!$C$5 -> 1353.3125 | E21: =(Constituyentes!$E$6+Constituyentes!$F$6*MIN(MAX($C21,Constituyentes!$H$6),Constituyentes!$I$6)+Constituyentes!$G$6/MIN(MAX($C21,Constituyentes!$H$6),Constituyentes!$I$6)^2)/Constituyentes!$C$6 -> 1332.6236 | F21: =IF($C21<Constituyentes!$I$7,(Constituyentes!$E$7+Constituyentes!$F$7*MIN(MAX($C21,Constituyentes!$H$7),Constituyentes!$I$7)+Constituyentes!$G$7/MIN(MAX($C21,Constituyentes!$H$7),Constituyentes!$I$7)^2)/Constituyentes!$C$7,(Constituyentes!$E$8+Constituyentes!$F$8*MIN(MAX($C21,Constituyentes!$H$8),Constituyentes!$I$8)+Constituyentes!$G$8/MIN(MAX($C21,Constituyentes!$H$8),Constituyentes!$I$8)^2)/Constituyentes!$C$8) -> 1232.6535 | G21: =(Constituyentes!$E$9+Constituyentes!$F$9*MIN(MAX($C21,Constituyentes!$H$9),Constituyentes!$I$9)+Constituyentes!$G$9/MIN(MAX($C21,Constituyentes!$H$9),Constituyentes!$I$9)^2)/Constituyentes!$C$9 -> 1018.4305 | H21: =(Constituyentes!$E$10+Constituyentes!$F$10*MIN(MAX($C21,Constituyentes!$H$10),Constituyentes!$I$10)+Constituyentes!$G$10/MIN(MAX($C21,Constituyentes!$H$10),Constituyentes!$I$10)^2)/Constituyentes!$C$10 -> 1068.1051 | I21: =(Constituyentes!$E$11+Constituyentes!$F$11*MIN(MAX($C21,Constituyentes!$H$11),Constituyentes!$I$11)+Constituyentes!$G$11/MIN(MAX($C21,Constituyentes!$H$11),Constituyentes!$I$11)^2)/Constituyentes!$C$11 -> 962.39794 | J21: =(Constituyentes!$E$12+Constituyentes!$F$12*MIN(MAX($C21,Constituyentes!$H$12),Constituyentes!$I$12)+Constituyentes!$G$12/MIN(MAX($C21,Constituyentes!$H$12),Constituyentes!$I$12)^2)/Constituyentes!$C$12 -> 1421.3504 | K21: =(Constituyentes!$E$13+Constituyentes!$F$13*MIN(MAX($C21,Constituyentes!$H$13),Constituyentes!$I$13)+Constituyentes!$G$13/MIN(MAX($C21,Constituyentes!$H$13),Constituyentes!$I$13)^2)/Constituyentes!$C$13 -> 1022.2931 | L21: =(Constituyentes!$E$14+Constituyentes!$F$14*MIN(MAX($C21,Constituyentes!$H$14),Constituyentes!$I$14)+Constituyentes!$G$14/MIN(MAX($C21,Constituyentes!$H$14),Constituyentes!$I$14)^2)/Constituyentes!$C$14 -> 2072.919
B23: Límite 3R/M | C23: (Dulong-Petit) | D23: =Constituyentes!$J$5 -> 1237.8908 | E23: =Constituyentes!$J$6 -> 1223.1883 | F23: =Constituyentes!$J$8 -> 1245.4521 | G23: =Constituyentes!$J$9 -> 889.61606 | H23: =Constituyentes!$J$10 -> 781.00734 | I23: =Constituyentes!$J$11 -> 936.95064 | J23: =Constituyentes!$J$12 -> 1207.3525 | K23: =Constituyentes!$J$13 -> 794.41271 | L23: =Constituyentes!$J$14 -> 2076.7213

Sheet Propiedades - Capa
B2: 05 · Tabla consolidada de propiedades y reparto térmico
B4: Capa | C4: Material | D4: e (mm) | E4: ρ (kg/m³) | F4: k (W/mK) | J4: k media (W/mK) | K4: cp a 1500°C | L4: ρCp (J/m³K) | M4: α (m²/s) | N4: R" (m²K/W) | O4: C" (J/m²K) | P4: T máx servicio (°C)
B5: 1 | C5: Trabajo — ANCARBON C F5L10 | D5: 127 | E5: 2990 | F5: (538 - 1000°C) | J5: 7.5 | K5: ='[1]Cp - Capas'!C20 -> 1406.1826 | L5: =E5*K5 -> 4204486 | M5: =J5/L5 -> 1.783809e-06 | N5: =D5/1000/F6 -> 0.016933333 | O5: =L5*D5/1000 -> 533969.73 | P5: 1700
F6: 7.5
B7: 2 | C7: Junta de sello — COMPAC DRY B83P | D7: 13 | E7: 2147 | F7: 400°C | G7: 800°C | H7: 1000°C | I7: 1200°C | J7: =AVERAGE(F8:I8) -> 1.6666667 | K7: ='[1]Cp - Capas'!D20 -> 1293.0706 | L7: =E7*K7 -> 2776222.6 | M7: =J7/L7 -> 6.0033611e-07 | N7: =D7/1000/G8 -> 0.0078787879 | O7: =L7*D7/1000 -> 36090.893 | P7: 1700
F8: 1.6 | G8: 1.65 | I8: 1.75
B9: 3 | C9: Seguridad — RESISTAL B65 | D9: 76 | E9: 2570 | F9: 400°C | G9: 800°C | H9: 1000°C | I9: 1200°C | J9: =AVERAGE(F10:I10) -> 1.9025 | K9: ='[1]Cp - Capas'!E20 -> 1281.8259 | L9: =E9*K9 -> 3294292.5 | M9: =J9/L9 -> 5.7751398e-07 | N9: =D9/1000/G10 -> 0.04 | O9: =L9*D9/1000 -> 250366.23 | P9: 1600
F10: 2.09 | G10: 1.9 | H10: 1.84 | I10: 1.78
B11: 4 | C11: Aislante — SKAMOL VIP 12 HT | D11: 13 | E11: 1400 | F11: 200°C | G11: 400°C | H11: 600°C | I11: 800°C | J11: =AVERAGE(F12:I12) -> 0.32 | K11: ='[1]Cp - Capas'!F20 -> 1245.2802 | L11: =E11*K11 -> 1743392.3 | M11: =J11/L11 -> 1.8355019e-07 | N11: =D11/1000/G12 -> 0.041935484 | O11: =L11*D11/1000 -> 22664.101 | P11: 1250
F12: 0.32 | G12: 0.31 | H12: 0.31 | I12: 0.34
B13: 5 | C13: Coraza — ACERO ASTM A516 | D13: 35 | E13: 7850 | F13: 35.3 | G13: 35.3 | H13: 35.3 | I13: 35.3 | J13: =AVERAGE(F13:I13) -> 35.3 | K13: 400 | L13: =E13*K13 -> 3140000 | M13: =J13/L13 -> 1.1242038e-05 | N13: =D13/1000/G13 -> 0.00099150142 | O13: =L13*D13/1000 -> 109900 | P13: 450
C14: TOTALES | D14: =SUM(D5:D13) -> 264 | N14: =SUM(N5:N13) -> 0.10773911 | O14: =SUM(O5:O13) -> 952990.95
B16: Reparto Térmico
B17: Capa | C17: Material | D17: % de la resistencia | E17: % de la capacidad térmica
B18: =B5 -> 1 | C18: =C5 -> Trabajo — ANCARBON C F5L10 | D18: =N5/$N$14 -> 0.1571698 | E18: =O5/$O$14 -> 0.56030933
B19: =B7 -> 2 | C19: =C7 -> Junta de sello — COMPAC DRY B83P | D19: =N7/$N$14 -> 0.073128394 | E19: =O7/$O$14 -> 0.037871181
B20: =B9 -> 3 | C20: =C9 -> Seguridad — RESISTAL B65 | D20: =N9/$N$14 -> 0.37126723 | E20: =O9/$O$14 -> 0.26271627
B21: =B11 -> 4 | C21: =C11 -> Aislante — SKAMOL VIP 12 HT | D21: =N11/$N$14 -> 0.38923178 | E21: =O11/$O$14 -> 0.023782073
B22: =B13 -> 5 | C22: =C13 -> Coraza — ACERO ASTM A516 | D22: =N13/$N$14 -> 0.0092027997 | E22: =O13/$O$14 -> 0.11532114
B23: Constante de tiempo del revestimiento (hrs) | D23: =N14*O14/3600 -> 28.520665 | E23: h (τ = R"·C")

Sheet Cp - Capas
B2: Cp(T) por capa [J/kg·K]
B3: cp_capa(T) = Σ wᵢ·cp,ᵢ(T)
B4: T (°C) | C4: 1 Trabajo MgO-C | D4: 2 Junta de sello bauxita | E4: 3 Seguridad Al2O3-SiO2 | F4: 4 Aislante vermiculita | G4: 5 Coraza acero (tabla)
B5: ='Cp - Constituyentes'!B5 -> 25 | C5: =SUMPRODUCT('CQ''s'!$D$13:$L$13,'Cp - Constituyentes'!$D5:$L5) -> 895.24088 | D5: =SUMPRODUCT('CQ''s'!$D$14:$L$14,'Cp - Constituyentes'!$D5:$L5) -> 763.94661 | E5: =SUMPRODUCT('CQ''s'!$D$15:$L$15,'Cp - Constituyentes'!$D5:$L5) -> 759.49603 | F5: =SUMPRODUCT('CQ''s'!$D$16:$L$16,'Cp - Constituyentes'!$D5:$L5) -> 797.99542 | G5: 434
B6: ='Cp - Constituyentes'!B6 -> 100 | C6: =SUMPRODUCT('CQ''s'!$D$13:$L$13,'Cp - Constituyentes'!$D6:$L6) -> 1034.7812 | D6: =SUMPRODUCT('CQ''s'!$D$14:$L$14,'Cp - Constituyentes'!$D6:$L6) -> 911.35069 | E6: =SUMPRODUCT('CQ''s'!$D$15:$L$15,'Cp - Constituyentes'!$D6:$L6) -> 901.81727 | F6: =SUMPRODUCT('CQ''s'!$D$16:$L$16,'Cp - Constituyentes'!$D6:$L6) -> 909.43231 | G6: 470
B7: ='Cp - Constituyentes'!B7 -> 200 | C7: =SUMPRODUCT('CQ''s'!$D$13:$L$13,'Cp - Constituyentes'!$D7:$L7) -> 1133.5067 | D7: =SUMPRODUCT('CQ''s'!$D$14:$L$14,'Cp - Constituyentes'!$D7:$L7) -> 1018.07 | E7: =SUMPRODUCT('CQ''s'!$D$15:$L$15,'Cp - Constituyentes'!$D7:$L7) -> 1008.6948 | F7: =SUMPRODUCT('CQ''s'!$D$16:$L$16,'Cp - Constituyentes'!$D7:$L7) -> 1000.9649 | G7: 510
B8: ='Cp - Constituyentes'!B8 -> 300 | C8: =SUMPRODUCT('CQ''s'!$D$13:$L$13,'Cp - Constituyentes'!$D8:$L8) -> 1190.5696 | D8: =SUMPRODUCT('CQ''s'!$D$14:$L$14,'Cp - Constituyentes'!$D8:$L8) -> 1081.9381 | E8: =SUMPRODUCT('CQ''s'!$D$15:$L$15,'Cp - Constituyentes'!$D8:$L8) -> 1076.0298 | F8: =SUMPRODUCT('CQ''s'!$D$16:$L$16,'Cp - Constituyentes'!$D8:$L8) -> 1065.2801 | G8: 550
B9: ='Cp - Constituyentes'!B9 -> 400 | C9: =SUMPRODUCT('CQ''s'!$D$13:$L$13,'Cp - Constituyentes'!$D9:$L9) -> 1228.7562 | D9: =SUMPRODUCT('CQ''s'!$D$14:$L$14,'Cp - Constituyentes'!$D9:$L9) -> 1126.3915 | E9: =SUMPRODUCT('CQ''s'!$D$15:$L$15,'Cp - Constituyentes'!$D9:$L9) -> 1125.4492 | F9: =SUMPRODUCT('CQ''s'!$D$16:$L$16,'Cp - Constituyentes'!$D9:$L9) -> 1117.2637 | G9: 590
B10: ='Cp - Constituyentes'!B10 -> 500 | C10: =SUMPRODUCT('CQ''s'!$D$13:$L$13,'Cp - Constituyentes'!$D10:$L10) -> 1257.1638 | D10: =SUMPRODUCT('CQ''s'!$D$14:$L$14,'Cp - Constituyentes'!$D10:$L10) -> 1160.7869 | E10: =SUMPRODUCT('CQ''s'!$D$15:$L$15,'Cp - Constituyentes'!$D10:$L10) -> 1165.5872 | F10: =SUMPRODUCT('CQ''s'!$D$16:$L$16,'Cp - Constituyentes'!$D10:$L10) -> 1162.859 | G10: 640
B11: ='Cp - Constituyentes'!B11 -> 600 | C11: =SUMPRODUCT('CQ''s'!$D$13:$L$13,'Cp - Constituyentes'!$D11:$L11) -> 1279.0381 | D11: =SUMPRODUCT('CQ''s'!$D$14:$L$14,'Cp - Constituyentes'!$D11:$L11) -> 1172.1309 | E11: =SUMPRODUCT('CQ''s'!$D$15:$L$15,'Cp - Constituyentes'!$D11:$L11) -> 1162.8042 | F11: =SUMPRODUCT('CQ''s'!$D$16:$L$16,'Cp - Constituyentes'!$D11:$L11) -> 1143.39 | G11: 700
B12: ='Cp - Constituyentes'!B12 -> 700 | C12: =SUMPRODUCT('CQ''s'!$D$13:$L$13,'Cp - Constituyentes'!$D12:$L12) -> 1298.0515 | D12: =SUMPRODUCT('CQ''s'!$D$14:$L$14,'Cp - Constituyentes'!$D12:$L12) -> 1190.8108 | E12: =SUMPRODUCT('CQ''s'!$D$15:$L$15,'Cp - Constituyentes'!$D12:$L12) -> 1180.6071 | F12: =SUMPRODUCT('CQ''s'!$D$16:$L$16,'Cp - Constituyentes'!$D12:$L12) -> 1160.0481 | G12: 800
B13: ='Cp - Constituyentes'!B13 -> 800 | C13: =SUMPRODUCT('CQ''s'!$D$13:$L$13,'Cp - Constituyentes'!$D13:$L13) -> 1314.6342 | D13: =SUMPRODUCT('CQ''s'!$D$14:$L$14,'Cp - Constituyentes'!$D13:$L13) -> 1206.6764 | E13: =SUMPRODUCT('CQ''s'!$D$15:$L$15,'Cp - Constituyentes'!$D13:$L13) -> 1196.0252 | F13: =SUMPRODUCT('CQ''s'!$D$16:$L$16,'Cp - Constituyentes'!$D13:$L13) -> 1173.0719 | G13: 900
B14: ='Cp - Constituyentes'!B14 -> 900 | C14: =SUMPRODUCT('CQ''s'!$D$13:$L$13,'Cp - Constituyentes'!$D14:$L14) -> 1329.7459 | D14: =SUMPRODUCT('CQ''s'!$D$14:$L$14,'Cp - Constituyentes'!$D14:$L14) -> 1221.1396 | E14: =SUMPRODUCT('CQ''s'!$D$15:$L$15,'Cp - Constituyentes'!$D14:$L14) -> 1210.2888 | F14: =SUMPRODUCT('CQ''s'!$D$16:$L$16,'Cp - Constituyentes'!$D14:$L14) -> 1185.5562 | G14: 650
B15: ='Cp - Constituyentes'!B15 -> 1000 | C15: =SUMPRODUCT('CQ''s'!$D$13:$L$13,'Cp - Constituyentes'!$D15:$L15) -> 1343.8301 | D15: =SUMPRODUCT('CQ''s'!$D$14:$L$14,'Cp - Constituyentes'!$D15:$L15) -> 1234.6232 | E15: =SUMPRODUCT('CQ''s'!$D$15:$L$15,'Cp - Constituyentes'!$D15:$L15) -> 1223.7462 | F15: =SUMPRODUCT('CQ''s'!$D$16:$L$16,'Cp - Constituyentes'!$D15:$L15) -> 1197.6635 | G15: 655
B16: ='Cp - Constituyentes'!B16 -> 1100 | C16: =SUMPRODUCT('CQ''s'!$D$13:$L$13,'Cp - Constituyentes'!$D16:$L16) -> 1357.1748 | D16: =SUMPRODUCT('CQ''s'!$D$14:$L$14,'Cp - Constituyentes'!$D16:$L16) -> 1247.4019 | E16: =SUMPRODUCT('CQ''s'!$D$15:$L$15,'Cp - Constituyentes'!$D16:$L16) -> 1236.6232 | F16: =SUMPRODUCT('CQ''s'!$D$16:$L$16,'Cp - Constituyentes'!$D16:$L16) -> 1209.4996 | G16: 665
... B21: ='Cp - Constituyentes'!B21 -> 1600 | C21: =SUMPRODUCT('CQ''s'!$D$13:$L$13,'Cp - Constituyentes'!$D21:$L21) -> 1417.7143 | D21: =SUMPRODUCT('CQ''s'!$D$14:$L$14,'Cp - Constituyentes'!$D21:$L21) -> 1302.4632 | E21: =SUMPRODUCT('CQ''s'!$D$15:$L$15,'Cp - Constituyentes'!$D21:$L21) -> 1289.5535 | F21: =SUMPRODUCT('CQ''s'!$D$16:$L$16,'Cp - Constituyentes'!$D21:$L21) -> 1248.8918 | G21: 700
B23: Verificación obligatoria contra el límite de Dulong-Petit
B24: Concepto | C24: 1 Trabajo | D24: 2 Junta | E24: 3 Seguridad | F24: 4 Aislante | G24: 5 Coraza
B25: Cp NKR a 1300 °C | C25: =C18 -> 1382.3615 | D25: =D18 -> 1271.5266 | E25: =E18 -> 1261.1979 | F25: =F18 -> 1230.2033 | G25: n/a
B26: Límite 3R/M | C26: =SUMPRODUCT('CQ''s'!$D$13:$L$13,'Cp - Constituyentes'!$D$23:$L$23) -> 1313.8793 | D26: =SUMPRODUCT('CQ''s'!$D$14:$L$14,'Cp - Constituyentes'!$D$23:$L$23) -> 1208.3324 | E26: =SUMPRODUCT('CQ''s'!$D$15:$L$15,'Cp - Constituyentes'!$D$23:$L$23) -> 1213.8437 | F26: =SUMPRODUCT('CQ''s'!$D$16:$L$16,'Cp - Constituyentes'!$D$23:$L$23) -> 1173.1805 | G26: n/a
B27: Exceso sobre 3R | C27: =C25/C26-1 -> 0.05212216 | D27: =D25/D26-1 -> 0.052298673 | E27: =E25/E26-1 -> 0.039011785 | F27: =F25/F26-1 -> 0.048605323
B28: OK / NO OK | C28: =IF(AND(C27>=-0.02,C27<=0.15),"OK","REVISAR") -> OK | D28: =IF(AND(D27>=-0.02,D27<=0.15),"OK","REVISAR") -> OK | E28: =IF(AND(E27>=-0.02,E27<=0.15),"OK","REVISAR") -> OK | F28: =IF(AND(F27>=-0.02,F27<=0.15),"OK","REVISAR") -> OK
B29: Cp medio 400–1300 °C | C29: =AVERAGE(C9:C18) -> 1316.073 | D29: =AVERAGE(D9:D18) -> 1209.1148 | E29: =AVERAGE(E9:E18) -> 1201.1401 | F29: =AVERAGE(F9:F18) -> 1179.9668 | G29: =AVERAGE(G9:G18) -> 696

Sheet Estacionario
B2: Estacionario - Olla llena
B3: q' = ΔT / [1/(2πr₁hint) + Σ ln(rᵢ₊₁/rᵢ)/(2πkᵢ) + 1/(2πrext·hext)].
B5: Entradas
B6: r₁ interior (m) | C6: 2.825
B7: H útil (m) | C7: 1.26
B8: T del acero (°C) | C8: 1562
B9: h interior (W/m²K) | C9: 1000
B10: T ambiente de nave (°C) | C10: 35
B11: h exterior (W/m²K) | C11: 33
B13: Resistencias por capa (por metro de altura)
B14: Capa | C14: e (mm) | D14: r int (m) | E14: r ext (m) | F14: k media (W/m·K) | G14: R' (m·K/W) | H14: T interfaz (°C)
B15: Convección interior | D15: =C6 -> 2.825 | G15: =1/(2*PI()*C6*C9) -> 5.6338033e-05 | H15: =C8 -> 1562
B16: ='Propiedades - Capa'!C5 -> Trabajo — ANCARBON C F5L10 | C16: ='Propiedades - Capa'!D5 -> 127 | D16: =C6 -> 2.825 | E16: =D16+C16/1000 -> 2.952 | F16: ='Propiedades - Capa'!J5 -> 7.5 | G16: =LN(E16/D16)/(2*PI()*F16) -> 0.00093316877 | H16: =H15-$C$25*G15 -> 1550.1515
B17: ='Propiedades - Capa'!C7 -> Junta de sello — COMPAC DRY B83P | C17: ='Propiedades - Capa'!D7 -> 13 | D17: =E16 -> 2.952 | E17: =D17+C17/1000 -> 2.965 | F17: ='Propiedades - Capa'!J7 -> 1.6666667 | G17: =LN(E17/D17)/(2*PI()*F17) -> 0.0004196081 | H17: =H16-$C$25*G16 -> 1353.8967
B18: ='Propiedades - Capa'!C9 -> Seguridad — RESISTAL B65 | C18: ='Propiedades - Capa'!D9 -> 76 | D18: =E17 -> 2.965 | E18: =D18+C18/1000 -> 3.041 | F18: ='Propiedades - Capa'!J9 -> 1.9025 | G18: =LN(E18/D18)/(2*PI()*F18) -> 0.0021172732 | H18: =H17-$C$25*G17 -> 1265.6489
B19: ='Propiedades - Capa'!C11 -> Aislante — SKAMOL VIP 12 HT | C19: ='Propiedades - Capa'!D11 -> 13 | D19: =E18 -> 3.041 | E19: =D19+C19/1000 -> 3.054 | F19: ='Propiedades - Capa'!J11 -> 0.32 | G19: =LN(E19/D19)/(2*PI()*F19) -> 0.0021216339 | H19: =H18-$C$25*G18 -> 820.36485
B20: ='Propiedades - Capa'!C13 -> Coraza — ACERO ASTM A516 | C20: ='Propiedades - Capa'!D13 -> 35 | D20: =E19 -> 3.054 | E20: =D20+C20/1000 -> 3.089 | F20: ='Propiedades - Capa'!J13 -> 35.3 | G20: =LN(E20/D20)/(2*PI()*F20) -> 5.1376871e-05 | H20: =H19-$C$25*G19 -> 374.16374
B21: Convección exterior | D21: =E20 -> 3.089 | G21: =1/(2*PI()*E20*C11) -> 0.0015613069 | H21: =H20-$C$25*G20 -> 363.35866
B23: Resultados
B24: R' total (m·K/W) | C24: =SUM(G15:G21) -> 0.0072607058
B25: q' (W/m de altura) | C25: =(C8-C10)/C24 -> 210310.13 | D25: ΔT entre acero y ambiente
B26: q" en la cara caliente (W/m²) | C26: =C25/(2*PI()*C6) -> 11848.459
B27: Pérdida por la pared (kW) | C27: =C25*C7/1000 -> 264.99077 | D27: En toda la altura útil
B29: Criterio de cordura: la cara fría debe quedar entre 250 y 400 °C. Fuera de esa banda, revisar k del aislante o h exterior antes de seguir.
B30: La formulación plana subestima el flujo ~13 % con e/r₁ = 0.18: usar cilíndrica.
B32: Verificación contra la temperatura máxima de servicio | C32: T en su cara caliente (°C) | D32: T máx (°C) | E32: Margen (°C) | F32: Veredicto
B33: =B16 -> Trabajo — ANCARBON C F5L10 | C33: =H16 -> 1550.1515 | D33: ='Propiedades - Capa'!P5 -> 1700 | E33: =D33-C33 -> 149.84846 | F33: =IF(E33<0,"EXCEDE",IF(E33<50,"AL LÍMITE","OK")) -> OK
B34: =B17 -> Junta de sello — COMPAC DRY B83P | C34: =H17 -> 1353.8967 | D34: ='Propiedades - Capa'!P7 -> 1700 | E34: =D34-C34 -> 346.10331 | F34: =IF(E34<0,"EXCEDE",IF(E34<50,"AL LÍMITE","OK")) -> OK
B35: =B18 -> Seguridad — RESISTAL B65 | C35: =H18 -> 1265.6489 | D35: ='Propiedades - Capa'!P9 -> 1600 | E35: =D35-C35 -> 334.35114 | F35: =IF(E35<0,"EXCEDE",IF(E35<50,"AL LÍMITE","OK")) -> OK
B36: =B19 -> Aislante — SKAMOL VIP 12 HT | C36: =H19 -> 820.36485 | D36: ='Propiedades - Capa'!P11 -> 1250 | E36: =D36-C36 -> 429.63515 | F36: =IF(E36<0,"EXCEDE",IF(E36<50,"AL LÍMITE","OK")) -> OK
B37: =B20 -> Coraza — ACERO ASTM A516 | C37: =H20 -> 374.16374 | D37: ='Propiedades - Capa'!P13 -> 450 | E37: =D37-C37 -> 75.836261 | F37: =IF(E37<0,"EXCEDE",IF(E37<50,"AL LÍMITE","OK")) -> OK
B39: Este chequeo es sobre el estacionario de olla llena, que es la cota superior del perfil: si una capa sale AL LÍMITE aquí, en operación real probablemente esté por debajo. Aun así, para la vermiculita conviene confirmarlo con el proveedor antes de fijar el diseño de capas.
B41: Tabla auxiliar de la gráfica — perfil desde la cara fría
B42: Punto | C42: x desde cara fría (m) | D42: T (°C)
B43: Cara fría de la coraza | C43: 0 | D43: =H21 -> 363.35866
B44: Interfaz aislante / coraza | C44: =C43+C20/1000 -> 0.035 | D44: =H20 -> 374.16374
B45: Interfaz seguridad / aislante | C45: =C44+C19/1000 -> 0.048 | D45: =H19 -> 820.36485
B46: Interfaz junta seca / seguridad | C46: =C45+C18/1000 -> 0.124 | D46: =H18 -> 1265.6489
B47: Interfaz trabajo / junta seca | C47: =C46+C17/1000 -> 0.137 | D47: =H17 -> 1353.8967
B48: Cara caliente | C48: =C47+C16/1000 -> 0.264 | D48: =H16 -> 1550.1515
...

Sheet 07_Enfriamiento
B2: 07 · Estimación analítica del enfriamiento de la cara caliente (olla vacía)
B3: Sólido semiinfinito con frontera radiativa linealizada: (Ts−T∞)/(Ti−T∞) = exp(β²)·erfc(β), β = h_r·√(αt)/k. Sirve como cota y como prueba de cordura del código transitorio, no como resultado final.
B5: Entradas
B6: Ti — cara caliente al fin de colado (°C) | C6: =Estacionario!H16 -> 1550.1515 | D6: Del estacionario de olla llena
B7: T∞ — ambiente que ve la boca (°C) | C7: 35
B8: r₁ (m) | C8: =Estacionario!C6 -> 2.825
B9: H útil (m) | C9: =Estacionario!C7 -> 1.26
B10: ε efectiva de cavidad, F = r/(2H+r) | C10: =C8/(2*C9+C8) -> 0.52853134 | D10: Usar ε desnuda sobreestima ~5 veces la pérdida
B11: k de la capa 1 (W/m·K) | C11: ='Propiedades - Capa'!G5 -> 0
B12: ρcp de la capa 1 a 800 °C (J/m³K) | C12: ='Propiedades - Capa'!K5 -> 1406.1826 | D12: Con cp de NKR
B13: α de la capa 1 (m²/s) | C13: =C11/C12 -> 0
B14: h_r evaluado en Ti (W/m²K) | C14: =C10*0.0000000567*((C6+273.15)+(C7+273.15))*((C6+273.15)^2+(C7+273.15)^2) -> 218.41238 | D14: h_r = εσ(Ts+T∞)(Ts²+T∞²)
B16: Curva de enfriamiento
B17: t (min) | C17: t (s) | D17: √(αt) (m) | E17: β | F17: exp(β²)·erfc(β) | G17: Ts (°C)
B18: 5 | C18: =B18*60 -> 300 | D18: =SQRT($C$13*C18) -> 0 | E18: =$C$14*D18/$C$11 -> #DIV/0! | F18: =IFERROR(EXP(E18^2)*ERFC(E18),0) -> 0 | G18: =$C$7+($C$6-$C$7)*F18 -> 35
B19: 10 | C19: =B19*60 -> 600 | D19: =SQRT($C$13*C19) -> 0 | E19: =$C$14*D19/$C$11 -> #DIV/0! | F19: =IFERROR(EXP(E19^2)*ERFC(E19),0) -> 0 | G19: =$C$7+($C$6-$C$7)*F19 -> 35
B20: 20 | C20: =B20*60 -> 1200 | D20: =SQRT($C$13*C20) -> 0 | E20: =$C$14*D20/$C$11 -> #DIV/0! | F20: =IFERROR(EXP(E20^2)*ERFC(E20),0) -> 0 | G20: =$C$7+($C$6-$C$7)*F20 -> 35
B21: 30 | C21: =B21*60 -> 1800 | D21: =SQRT($C$13*C21) -> 0 | E21: =$C$14*D21/$C$11 -> #DIV/0! | F21: =IFERROR(EXP(E21^2)*ERFC(E21),0) -> 0 | G21: =$C$7+($C$6-$C$7)*F21 -> 35
B22: 45 | C22: =B22*60 -> 2700 | D22: =SQRT($C$13*C22) -> 0 | E22: =$C$14*D22/$C$11 -> #DIV/0! | F22: =IFERROR(EXP(E22^2)*ERFC(E22),0) -> 0 | G22: =$C$7+($C$6-$C$7)*F22 -> 35
B23: 60 | C23: =B23*60 -> 3600 | D23: =SQRT($C$13*C23) -> 0 | E23: =$C$14*D23/$C$11 -> #DIV/0! | F23: =IFERROR(EXP(E23^2)*ERFC(E23),0) -> 0 | G23: =$C$7+($C$6-$C$7)*F23 -> 35
B24: 90 | C24: =B24*60 -> 5400 | D24: =SQRT($C$13*C24) -> 0 | E24: =$C$14*D24/$C$11 -> #DIV/0! | F24: =IFERROR(EXP(E24^2)*ERFC(E24),0) -> 0 | G24: =$C$7+($C$6-$C$7)*F24 -> 35
B25: 120 | C25: =B25*60 -> 7200 | D25: =SQRT($C$13*C25) -> 0 | E25: =$C$14*D25/$C$11 -> #DIV/0! | F25: =IFERROR(EXP(E25^2)*ERFC(E25),0) -> 0 | G25: =$C$7+($C$6-$C$7)*F25 -> 35
B26: 180 | C26: =B26*60 -> 10800 | D26: =SQRT($C$13*C26) -> 0 | E26: =$C$14*D26/$C$11 -> #DIV/0! | F26: =IFERROR(EXP(E26^2)*ERFC(E26),0) -> 0 | G26: =$C$7+($C$6-$C$7)*F26 -> 35
B27: 240 | C27: =B27*60 -> 14400 | D27: =SQRT($C$13*C27) -> 0 | E27: =$C$14*D27/$C$11 -> #DIV/0! | F27: =IFERROR(EXP(E27^2)*ERFC(E27),0) -> 0 | G27: =$C$7+($C$6-$C$7)*F27 -> 35
B29: h_r evaluado en Ti enfría de más: entre 1550 y 700 °C el h_r cae un factor ~5. La banda entre esta cota y la que resulta de iterar la temperatura de referencia es amplia — y es exactamente la razón por la que el término T⁴ debe quedar EXPLÍCITO en el transitorio, con 2–3 iteraciones por paso.
B30: Verificación cualitativa decisiva del código: al enfriarse, el máximo de temperatura debe migrar hacia el interior del refractario. Si se queda en la cara caliente, la condición de frontera radiativa está mal.

Sheet 08_Fuentes
B2: 08 · Semáforo de datos
B3: Estados: MEDIDA (ensayo propio) · FICHA (dato del proveedor) · NKR (calculada en este libro) · LITERATURA · SUPUESTA (a sustituir).
B5: Capa | C5: Propiedad | D5: Estado | E5: Fuente | F5: Nota
B6: 1 | C6: Composición química | D6: FICHA | E6: Proveedor, 18-ago-2026 | F6: Base calcinada + 10 % C fijo
B7: 1 | C7: cp(T) | D7: NKR | E7: Este libro, hoja 04 | F7: ±3–5 %; sustituir por DSC ASTM E1269 si se requiere
B8: 1 | C8: ρ | D8: FICHA | E8: Proveedor (bulk red. 1000 °C) | F8: 2990 kg/m³ es el valor de olla en servicio (ligante ya coquizado)
B9: 1 | C9: k(T) | D9: FICHA parcial | E9: Proveedor, un punto a 1000 °C | F9: Pedir curva ASTM C1113 en atmósfera reductora
B10: 2 | C10: Composición química | D10: FICHA | E10: Proveedor, 18-ago-2026 | F10: Quemada 1025 °C, ISO 12677; huella de bauxita calcinada
B11: 2 | C11: cp(T) | D11: NKR | E11: Este libro, hoja 04
B12: 2 | C12: ρ instalada | D12: SUPUESTA | E12: Banda 2100–2500 kg/m³ | F12: Pedir rendimiento (kg/m³) al proveedor: es el dato más fácil de conseguir
B13: 2 | C13: k(T) | D13: FICHA | E13: Proveedor, 3 puntos | F13: 1.60–1.75 W/m·K; el valor real duplica el supuesto de v2
B14: 3 | C14: Composición química | D14: FICHA | E14: Proveedor, 19-ago-2026
B15: 3 | C15: cp(T) | D15: NKR | E15: Este libro, hoja 04 | F15: Coherente: ρ_real = 2.57/(1−0.20) = 3.21 g/cm³, propio de mullita + corindón
B16: 3 | C16: ρ, porosidad | D16: FICHA | E16: 2.57 g/cm³, 20 % vol.
B17: 3 | C17: k(T) | D17: FICHA | E17: Proveedor, 4 puntos
B18: 4 | C18: Composición química | D18: FICHA | E18: Proveedor, 19-ago-2026 | F18: Vermiculita exfoliada; LOI 2.8 % excluida del cp
B19: 4 | C19: cp(T) | D19: NKR | E19: Este libro, hoja 04 | F19: Incluye Fe2O3 y K2O explícitos; Na2O aporta < 0.01 %
B20: 4 | C20: k(T) | D20: LITERATURA | E20: Vermiculita exfoliada, banda típica | F20: 0.10→0.19 W/m·K creciente. Sin medir: ver sensibilidad en la hoja 09. PRIORIDAD MÁXIMA
B21: 4 | C21: ρ | D21: SUPUESTA | E21: Banda 300–450 kg/m³ | F21: 350 kg/m³ es coherente con vermiculita, pero pedir el dato de ficha
B22: 4 | C22: T máx de servicio | D22: POR VERIFICAR | E22: Proveedor | F22: La vermiculita suele limitarse a ~1100 °C; la interfaz seguridad/aislante calcula ~1050 °C
B23: 5 | C23: cp(T) | D23: LITERATURA | E23: Incropera / Touloukian, AISI 1010 | F23: No aplica NKR: Curie 770 °C y α→γ 912 °C
B24: 5 | C24: Espesor | D24: POR VERIFICAR | E24: Planta | F24: 1.5 mm es atípico; afecta poco al perfil y mucho a la inercia
B25: — | C25: Duración del enfriamiento | D25: FALTA | E25: Planta | F25: Sigue siendo el dato de proceso más influyente del modelo

Sheet 09_Sensibilidad_aislante
B2: 09 · Sensibilidad del perfil a k del aislante (el único parámetro que falta y que manda)
B3: Se recalcula el estacionario de 06 variando sólo k del aislante; todo lo demás queda fijo. Mientras no haya medición, este es el rango honesto de resultados del modelo.
B5: k aislante (W/m·K) | C5: R' aislante | D5: R' total | E5: q' (W/m) | F5: Cara caliente (°C) | G5: Interfaz seguridad/aislante (°C) | H5: Cara fría (°C) | I5: Comentario
B6: 0.08 | C6: =LN(Estacionario!E19/Estacionario!D19)/(2*PI()*B6) -> 0.0084865357 | D6: =Estacionario!$C$24-Estacionario!$G$19+C6 -> 0.013625608 | E6: =(Estacionario!$C$8-Estacionario!$C$10)/D6 -> 112068.4 | F6: =Estacionario!$C$8-E6*Estacionario!$G$15 -> 1555.6863 | G6: =F6-E6*(Estacionario!$G$16+Estacionario!$G$17+Estacionario!$G$18) -> 1166.8033 | H6: =G6-E6*(C6+Estacionario!$G$20) -> 209.97316 | I6: Microporoso de alta calidad
B7: 0.1 | C7: =LN(Estacionario!E19/Estacionario!D19)/(2*PI()*B7) -> 0.0067892285 | D7: =Estacionario!$C$24-Estacionario!$G$19+C7 -> 0.0119283 | E7: =(Estacionario!$C$8-Estacionario!$C$10)/D7 -> 128014.88 | F7: =Estacionario!$C$8-E7*Estacionario!$G$15 -> 1554.7879 | G7: =F7-E7*(Estacionario!$G$16+Estacionario!$G$17+Estacionario!$G$18) -> 1110.5698 | H7: =G7-E7*(C7+Estacionario!$G$20) -> 234.87052 | I7: Vermiculita, extremo bajo (400 °C)
B8: 0.12 | C8: =LN(Estacionario!E19/Estacionario!D19)/(2*PI()*B8) -> 0.0056576905 | D8: =Estacionario!$C$24-Estacionario!$G$19+C8 -> 0.010796762 | E8: =(Estacionario!$C$8-Estacionario!$C$10)/D8 -> 141431.29 | F8: =Estacionario!$C$8-E8*Estacionario!$G$15 -> 1554.032 | G8: =F8-E8*(Estacionario!$G$16+Estacionario!$G$17+Estacionario!$G$18) -> 1063.2584 | H8: =G8-E8*(C8+Estacionario!$G$20) -> 255.81765
B9: 0.1467 | C9: =LN(Estacionario!E19/Estacionario!D19)/(2*PI()*B9) -> 0.0046279676 | D9: =Estacionario!$C$24-Estacionario!$G$19+C9 -> 0.0097670396 | E9: =(Estacionario!$C$8-Estacionario!$C$10)/D9 -> 156342.15 | F9: =Estacionario!$C$8-E9*Estacionario!$G$15 -> 1553.192 | G9: =F9-E9*(Estacionario!$G$16+Estacionario!$G$17+Estacionario!$G$18) -> 1010.6769 | H9: =G9-E9*(C9+Estacionario!$G$20) -> 279.09809 | I9: k media usada en 06
B10: 0.16 | C10: =LN(Estacionario!E19/Estacionario!D19)/(2*PI()*B10) -> 0.0042432678 | D10: =Estacionario!$C$24-Estacionario!$G$19+C10 -> 0.0093823398 | E10: =(Estacionario!$C$8-Estacionario!$C$10)/D10 -> 162752.58 | F10: =Estacionario!$C$8-E10*Estacionario!$G$15 -> 1552.8308 | G10: =F10-E10*(Estacionario!$G$16+Estacionario!$G$17+Estacionario!$G$18) -> 988.07123 | H10: =G10-E10*(C10+Estacionario!$G$20) -> 289.10673
B11: 0.19 | C11: =LN(Estacionario!E19/Estacionario!D19)/(2*PI()*B11) -> 0.0035732782 | D11: =Estacionario!$C$24-Estacionario!$G$19+C11 -> 0.0087123501 | E11: =(Estacionario!$C$8-Estacionario!$C$10)/D11 -> 175268.44 | F11: =Estacionario!$C$8-E11*Estacionario!$G$15 -> 1552.1257 | G11: =F11-E11*(Estacionario!$G$16+Estacionario!$G$17+Estacionario!$G$18) -> 943.93546 | H11: =G11-E11*(C11+Estacionario!$G$20) -> 308.64783 | I11: Vermiculita a 1200 °C
B12: 0.22 | C12: =LN(Estacionario!E19/Estacionario!D19)/(2*PI()*B12) -> 0.003086013 | D12: =Estacionario!$C$24-Estacionario!$G$19+C12 -> 0.0082250849 | E12: =(Estacionario!$C$8-Estacionario!$C$10)/D12 -> 185651.58 | F12: =Estacionario!$C$8-E12*Estacionario!$G$15 -> 1551.5408 | G12: =F12-E12*(Estacionario!$G$16+Estacionario!$G$17+Estacionario!$G$18) -> 907.32047 | H12: =G12-E12*(C12+Estacionario!$G$20) -> 324.85909
B13: 0.25 | C13: =LN(Estacionario!E19/Estacionario!D19)/(2*PI()*B13) -> 0.0027156914 | D13: =Estacionario!$C$24-Estacionario!$G$19+C13 -> 0.0078547633 | E13: =(Estacionario!$C$8-Estacionario!$C$10)/D13 -> 194404.33 | F13: =Estacionario!$C$8-E13*Estacionario!$G$15 -> 1551.0476 | G13: =F13-E13*(Estacionario!$G$16+Estacionario!$G$17+Estacionario!$G$18) -> 876.45488 | H13: =G13-E13*(C13+Estacionario!$G$20) -> 338.52482 | I13: Aislante degradado o mal instalado
B15: Lectura
B16: La cara caliente casi no se mueve: el aislante no la controla. Lo que se mueve mucho es la temperatura de la cara fría (coraza) y la de la interfaz seguridad/aislante — es decir, exactamente las dos cosas que se usan para validar el modelo contra planta y para juzgar el límite de servicio de la vermiculita.
